<sdf version='1.11'>
  <model name='humanoid'>
    <link name='base_link'>
      <inertial>
        <pose>0 0 1.132835820895522 0 0 0</pose>
        <mass>20.100000000000001</mass>
        <inertia>
          <ixx>1.9773783582089519</ixx>
          <ixy>0</ixy>
          <ixz>0</ixz>
          <iyy>1.9790783582089519</iyy>
          <iyz>0</iyz>
          <izz>0.2288</izz>
        </inertia>
      </inertial>
      <collision name='base_link_fixed_joint_lump__pelvis_link_collision'>
        <pose>0 0 0.84999999999999998 0 0 0</pose>
        <geometry>
          <cylinder>
            <length>0.22</length>
            <radius>0.17999999999999999</radius>
          </cylinder>
        </geometry>
        <surface>
          <contact>
            <ode/>
          </contact>
          <friction>
            <ode/>
          </friction>
        </surface>
      </collision>
      <collision name='base_link_fixed_joint_lump__torso_link_collision_1'>
        <pose>0 0 1.26 0 0 0</pose>
        <geometry>
          <cylinder>
            <length>0.59999999999999998</length>
            <radius>0.13</radius>
          </cylinder>
        </geometry>
        <surface>
          <contact>
            <ode/>
          </contact>
          <friction>
            <ode/>
          </friction>
        </surface>
      </collision>
      <collision name='base_link_fixed_joint_lump__head_link_collision_2'>
        <pose>0 0 1.6850000000000001 0 0 0</pose>
        <geometry>
          <box>
            <size>0.22 0.17999999999999999 0.25</size>
          </box>
        </geometry>
        <surface>
          <contact>
            <ode/>
          </contact>
          <friction>
            <ode/>
          </friction>
        </surface>
      </collision>
      <visual name='base_link_fixed_joint_lump__pelvis_link_visual'>
        <pose>0 0 0.84999999999999998 0 0 0</pose>
        <geometry>
          <cylinder>
            <length>0.22</length>
            <radius>0.17999999999999999</radius>
          </cylinder>
        </geometry>
        <material>
          <script>
            <name>Gazebo/White</name>
            <uri>file://media/materials/scripts/gazebo.material</uri>
          </script>
        </material>
      </visual>
      <visual name='base_link_fixed_joint_lump__torso_link_visual_1'>
        <pose>0 0 1.26 0 0 0</pose>
        <geometry>
          <cylinder>
            <length>0.59999999999999998</length>
            <radius>0.13</radius>
          </cylinder>
        </geometry>
        <material>
          <script>
            <name>Gazebo/White</name>
            <uri>file://media/materials/scripts/gazebo.material</uri>
          </script>
        </material>
      </visual>
      <visual name='base_link_fixed_joint_lump__head_link_visual_2'>
        <pose>0 0 1.6850000000000001 0 0 0</pose>
        <geometry>
          <box>
            <size>0.22 0.17999999999999999 0.25</size>
          </box>
        </geometry>
        <material>
          <script>
            <name>Gazebo/White</name>
            <uri>file://media/materials/scripts/gazebo.material</uri>
          </script>
        </material>
      </visual>
    </link>
    <joint name='pelvis_to_l_leg' type='revolute'>
      <pose relative_to='base_link'>0 0.12 0.73999999999999999 0 0 0</pose>
      <parent>base_link</parent>
      <child>l_leg_link</child>
      <axis>
        <xyz>1 0 0</xyz>
        <limit>
          <lower>-0.5</lower>
          <upper>0.5</upper>
          <effort>100</effort>
          <velocity>1</velocity>
        </limit>
        <dynamics>
          <damping>0.5</damping>
          <friction>0.10000000000000001</friction>
          <spring_reference>0</spring_reference>
          <spring_stiffness>0</spring_stiffness>
        </dynamics>
      </axis>
    </joint>
    <link name='l_leg_link'>
      <pose relative_to='pelvis_to_l_leg'>0 0 0 0 0 0</pose>
      <inertial>
        <pose>0 0 -0.375 0 0 0</pose>
        <mass>3</mass>
        <inertia>
          <ixx>0.14219999999999999</ixx>
          <ixy>0</ixy>
          <ixz>0</ixz>
          <iyy>0.14219999999999999</iyy>
          <iyz>0</iyz>
          <izz>0.0038</izz>
        </inertia>
      </inertial>
      <collision name='l_leg_link_collision'>
        <pose>0 0 -0.375 0 0 0</pose>
        <geometry>
          <cylinder>
            <length>0.75</length>
            <radius>0.050000000000000003</radius>
          </cylinder>
        </geometry>
        <surface>
          <contact>
            <ode/>
          </contact>
          <friction>
            <ode/>
          </friction>
        </surface>
      </collision>
      <visual name='l_leg_link_visual'>
        <pose>0 0 -0.375 0 0 0</pose>
        <geometry>
          <cylinder>
            <length>0.75</length>
            <radius>0.050000000000000003</radius>
          </cylinder>
        </geometry>
        <material>
          <script>
            <name>Gazebo/White</name>
            <uri>file://media/materials/scripts/gazebo.material</uri>
          </script>
        </material>
      </visual>
    </link>
    <joint name='l_wheel_joint' type='revolute'>
      <pose relative_to='l_leg_link'>0 0 -0.75 0 0 0</pose>
      <parent>l_leg_link</parent>
      <child>l_wheel_link</child>
      <axis>
        <xyz>0 1 0</xyz>
        <limit>
          <lower>-inf</lower>
          <upper>inf</upper>
        </limit>
        <dynamics>
          <damping>0.10000000000000001</damping>
          <friction>0.5</friction>
          <spring_reference>0</spring_reference>
          <spring_stiffness>0</spring_stiffness>
        </dynamics>
      </axis>
    </joint>
    <link name='l_wheel_link'>
      <pose relative_to='l_wheel_joint'>0 0 0 0 0 0</pose>
      <inertial>
        <pose>0 0 0 0 0 0</pose>
        <mass>1</mass>
        <inertia>
          <ixx>0.0025000000000000001</ixx>
          <ixy>0</ixy>
          <ixz>0</ixz>
          <iyy>0.0025000000000000001</iyy>
          <iyz>0</iyz>
          <izz>0.0050000000000000001</izz>
        </inertia>
      </inertial>
      <collision name='l_wheel_link_collision'>
        <pose>0 0 0 1.5708 0 0</pose>
        <geometry>
          <cylinder>
            <length>0.059999999999999998</length>
            <radius>0.10000000000000001</radius>
          </cylinder>
        </geometry>
        <surface>
          <contact>
            <ode/>
          </contact>
          <friction>
            <ode/>
          </friction>
        </surface>
      </collision>
      <visual name='l_wheel_link_visual'>
        <pose>0 0 0 1.5708 0 0</pose>
        <geometry>
          <cylinder>
            <length>0.059999999999999998</length>
            <radius>0.10000000000000001</radius>
          </cylinder>
        </geometry>
        <material>
          <script>
            <name>Gazebo/DarkGrey</name>
            <uri>file://media/materials/scripts/gazebo.material</uri>
          </script>
        </material>
      </visual>
    </link>
    <joint name='pelvis_to_r_leg' type='revolute'>
      <pose relative_to='base_link'>0 -0.12 0.73999999999999999 0 0 0</pose>
      <parent>base_link</parent>
      <child>r_leg_link</child>
      <axis>
        <xyz>1 0 0</xyz>
        <limit>
          <lower>-0.5</lower>
          <upper>0.5</upper>
          <effort>100</effort>
          <velocity>1</velocity>
        </limit>
        <dynamics>
          <damping>0.5</damping>
          <friction>0.10000000000000001</friction>
          <spring_reference>0</spring_reference>
          <spring_stiffness>0</spring_stiffness>
        </dynamics>
      </axis>
    </joint>
    <link name='r_leg_link'>
      <pose relative_to='pelvis_to_r_leg'>0 0 0 0 0 0</pose>
      <inertial>
        <pose>0 0 -0.375 0 0 0</pose>
        <mass>3</mass>
        <inertia>
          <ixx>0.14219999999999999</ixx>
          <ixy>0</ixy>
          <ixz>0</ixz>
          <iyy>0.14219999999999999</iyy>
          <iyz>0</iyz>
          <izz>0.0038</izz>
        </inertia>
      </inertial>
      <collision name='r_leg_link_collision'>
        <pose>0 0 -0.375 0 0 0</pose>
        <geometry>
          <cylinder>
            <length>0.75</length>
            <radius>0.050000000000000003</radius>
          </cylinder>
        </geometry>
        <surface>
          <contact>
            <ode/>
          </contact>
          <friction>
            <ode/>
          </friction>
        </surface>
      </collision>
      <visual name='r_leg_link_visual'>
        <pose>0 0 -0.375 0 0 0</pose>
        <geometry>
          <cylinder>
            <length>0.75</length>
            <radius>0.050000000000000003</radius>
          </cylinder>
        </geometry>
        <material>
          <script>
            <name>Gazebo/White</name>
            <uri>file://media/materials/scripts/gazebo.material</uri>
          </script>
        </material>
      </visual>
    </link>
    <joint name='r_wheel_joint' type='revolute'>
      <pose relative_to='r_leg_link'>0 0 -0.75 0 0 0</pose>
      <parent>r_leg_link</parent>
      <child>r_wheel_link</child>
      <axis>
        <xyz>0 1 0</xyz>
        <limit>
          <lower>-inf</lower>
          <upper>inf</upper>
        </limit>
        <dynamics>
          <damping>0.10000000000000001</damping>
          <friction>0.5</friction>
          <spring_reference>0</spring_reference>
          <spring_stiffness>0</spring_stiffness>
        </dynamics>
      </axis>
    </joint>
    <link name='r_wheel_link'>
      <pose relative_to='r_wheel_joint'>0 0 0 0 0 0</pose>
      <inertial>
        <pose>0 0 0 0 0 0</pose>
        <mass>1</mass>
        <inertia>
          <ixx>0.0025000000000000001</ixx>
          <ixy>0</ixy>
          <ixz>0</ixz>
          <iyy>0.0025000000000000001</iyy>
          <iyz>0</iyz>
          <izz>0.0050000000000000001</izz>
        </inertia>
      </inertial>
      <collision name='r_wheel_link_collision'>
        <pose>0 0 0 1.5708 0 0</pose>
        <geometry>
          <cylinder>
            <length>0.059999999999999998</length>
            <radius>0.10000000000000001</radius>
          </cylinder>
        </geometry>
        <surface>
          <contact>
            <ode/>
          </contact>
          <friction>
            <ode/>
          </friction>
        </surface>
      </collision>
      <visual name='r_wheel_link_visual'>
        <pose>0 0 0 1.5708 0 0</pose>
        <geometry>
          <cylinder>
            <length>0.059999999999999998</length>
            <radius>0.10000000000000001</radius>
          </cylinder>
        </geometry>
        <material>
          <script>
            <name>Gazebo/DarkGrey</name>
            <uri>file://media/materials/scripts/gazebo.material</uri>
          </script>
        </material>
      </visual>
    </link>
    <joint name='l_shoulder' type='revolute'>
      <pose relative_to='base_link'>0 0.185 1.46 0 0 0</pose>
      <parent>base_link</parent>
      <child>l_upper_arm_link</child>
      <axis>
        <xyz>0 1 0</xyz>
        <limit>
          <lower>-3.1400000000000001</lower>
          <upper>3.1400000000000001</upper>
          <effort>100</effort>
          <velocity>1</velocity>
        </limit>
        <dynamics>
          <damping>0.5</damping>
          <friction>0.10000000000000001</friction>
          <spring_reference>0</spring_reference>
          <spring_stiffness>0</spring_stiffness>
        </dynamics>
      </axis>
    </joint>
    <link name='l_upper_arm_link'>
      <pose relative_to='l_shoulder'>0 0 0 0 0 0</pose>
      <inertial>
        <pose>0 0 -0.17499999999999999 0 0 0</pose>
        <mass>2</mass>
        <inertia>
          <ixx>0.0223</ixx>
          <ixy>0</ixy>
          <ixz>0</ixz>
          <iyy>0.0223</iyy>
          <iyz>0</iyz>
          <izz>0.0040000000000000001</izz>
        </inertia>
      </inertial>
      <collision name='l_upper_arm_link_collision'>
        <pose>0 0 -0.17499999999999999 0 0 0</pose>
        <geometry>
          <box>
            <size>0.11 0.11 0.34999999999999998</size>
          </box>
        </geometry>
        <surface>
          <contact>
            <ode/>
          </contact>
          <friction>
            <ode/>
          </friction>
        </surface>
      </collision>
      <visual name='l_upper_arm_link_visual'>
        <pose>0 0 -0.17499999999999999 0 0 0</pose>
        <geometry>
          <box>
            <size>0.11 0.11 0.34999999999999998</size>
          </box>
        </geometry>
        <material>
          <script>
            <name>Gazebo/White</name>
            <uri>file://media/materials/scripts/gazebo.material</uri>
          </script>
        </material>
      </visual>
    </link>
    <joint name='l_elbow' type='revolute'>
      <pose relative_to='l_upper_arm_link'>0 0 -0.34999999999999998 0 0 0</pose>
      <parent>l_upper_arm_link</parent>
      <child>l_forearm_link</child>
      <axis>
        <xyz>0 1 0</xyz>
        <limit>
          <lower>-2.3500000000000001</lower>
          <upper>0</upper>
          <effort>100</effort>
          <velocity>1</velocity>
        </limit>
        <dynamics>
          <damping>0.5</damping>
          <friction>0.10000000000000001</friction>
          <spring_reference>0</spring_reference>
          <spring_stiffness>0</spring_stiffness>
        </dynamics>
      </axis>
    </joint>
    <link name='l_forearm_link'>
      <pose relative_to='l_elbow'>0 0 0 0 0 0</pose>
      <inertial>
        <pose>0 0 -0.14999999999999999 0 0 0</pose>
        <mass>1.5</mass>
        <inertia>
          <ixx>0.012</ixx>
          <ixy>0</ixy>
          <ixz>0</ixz>
          <iyy>0.012</iyy>
          <iyz>0</iyz>
          <izz>0.002</izz>
        </inertia>
      </inertial>
      <collision name='l_forearm_link_collision'>
        <pose>0 0 -0.14999999999999999 0 0 0</pose>
        <geometry>
          <box>
            <size>0.089999999999999997 0.089999999999999997 0.29999999999999999</size>
          </box>
        </geometry>
        <surface>
          <contact>
            <ode/>
          </contact>
          <friction>
            <ode/>
          </friction>
        </surface>
      </collision>
      <visual name='l_forearm_link_visual'>
        <pose>0 0 -0.14999999999999999 0 0 0</pose>
        <geometry>
          <box>
            <size>0.089999999999999997 0.089999999999999997 0.29999999999999999</size>
          </box>
        </geometry>
        <material>
          <script>
            <name>Gazebo/White</name>
            <uri>file://media/materials/scripts/gazebo.material</uri>
          </script>
        </material>
      </visual>
    </link>
    <joint name='r_shoulder' type='revolute'>
      <pose relative_to='base_link'>0 -0.185 1.46 0 0 0</pose>
      <parent>base_link</parent>
      <child>r_upper_arm_link</child>
      <axis>
        <xyz>0 1 0</xyz>
        <limit>
          <lower>-3.1400000000000001</lower>
          <upper>3.1400000000000001</upper>
          <effort>100</effort>
          <velocity>1</velocity>
        </limit>
        <dynamics>
          <damping>0.5</damping>
          <friction>0.10000000000000001</friction>
          <spring_reference>0</spring_reference>
          <spring_stiffness>0</spring_stiffness>
        </dynamics>
      </axis>
    </joint>
    <link name='r_upper_arm_link'>
      <pose relative_to='r_shoulder'>0 0 0 0 0 0</pose>
      <inertial>
        <pose>0 0 -0.17499999999999999 0 0 0</pose>
        <mass>2</mass>
        <inertia>
          <ixx>0.0223</ixx>
          <ixy>0</ixy>
          <ixz>0</ixz>
          <iyy>0.0223</iyy>
          <iyz>0</iyz>
          <izz>0.0040000000000000001</izz>
        </inertia>
      </inertial>
      <collision name='r_upper_arm_link_collision'>
        <pose>0 0 -0.17499999999999999 0 0 0</pose>
        <geometry>
          <box>
            <size>0.11 0.11 0.34999999999999998</size>
          </box>
        </geometry>
        <surface>
          <contact>
            <ode/>
          </contact>
          <friction>
            <ode/>
          </friction>
        </surface>
      </collision>
      <visual name='r_upper_arm_link_visual'>
        <pose>0 0 -0.17499999999999999 0 0 0</pose>
        <geometry>
          <box>
            <size>0.11 0.11 0.34999999999999998</size>
          </box>
        </geometry>
        <material>
          <script>
            <name>Gazebo/White</name>
            <uri>file://media/materials/scripts/gazebo.material</uri>
          </script>
        </material>
      </visual>
    </link>
    <joint name='r_elbow' type='revolute'>
      <pose relative_to='r_upper_arm_link'>0 0 -0.34999999999999998 0 0 0</pose>
      <parent>r_upper_arm_link</parent>
      <child>r_forearm_link</child>
      <axis>
        <xyz>0 1 0</xyz>
        <limit>
          <lower>-2.3500000000000001</lower>
          <upper>0</upper>
          <effort>100</effort>
          <velocity>1</velocity>
        </limit>
        <dynamics>
          <damping>0.5</damping>
          <friction>0.10000000000000001</friction>
          <spring_reference>0</spring_reference>
          <spring_stiffness>0</spring_stiffness>
        </dynamics>
      </axis>
    </joint>
    <link name='r_forearm_link'>
      <pose relative_to='r_elbow'>0 0 0 0 0 0</pose>
      <inertial>
        <pose>0 0 -0.14999999999999999 0 0 0</pose>
        <mass>1.5</mass>
        <inertia>
          <ixx>0.012</ixx>
          <ixy>0</ixy>
          <ixz>0</ixz>
          <iyy>0.012</iyy>
          <iyz>0</iyz>
          <izz>0.002</izz>
        </inertia>
      </inertial>
      <collision name='r_forearm_link_collision'>
        <pose>0 0 -0.14999999999999999 0 0 0</pose>
        <geometry>
          <box>
            <size>0.089999999999999997 0.089999999999999997 0.29999999999999999</size>
          </box>
        </geometry>
        <surface>
          <contact>
            <ode/>
          </contact>
          <friction>
            <ode/>
          </friction>
        </surface>
      </collision>
      <visual name='r_forearm_link_visual'>
        <pose>0 0 -0.14999999999999999 0 0 0</pose>
        <geometry>
          <box>
            <size>0.089999999999999997 0.089999999999999997 0.29999999999999999</size>
          </box>
        </geometry>
        <material>
          <script>
            <name>Gazebo/White</name>
            <uri>file://media/materials/scripts/gazebo.material</uri>
          </script>
        </material>
      </visual>
    </link>
    <plugin name='gz::sim::systems::DiffDrive' filename='gz-sim-diff-drive-system'>
      <left_joint>l_wheel_joint</left_joint>
      <right_joint>r_wheel_joint</right_joint>
      <wheel_separation>0.24</wheel_separation>
      <wheel_radius>0.10</wheel_radius>
      <topic>cmd_vel</topic>
      <odom_topic>odom</odom_topic>
      <frame_id>odom</frame_id>
      <child_frame_id>base_link</child_frame_id>
    </plugin>
    <plugin name='gz::sim::systems::JointStatePublisher' filename='gz-sim-joint-state-publisher-system'/>
    <frame name='torso_to_head' attached_to='torso_link'>
      <pose>0 0 0.42499999999999999 0 0 0</pose>
    </frame>
    <frame name='head_link' attached_to='torso_to_head'>
      <pose>0 0 0 0 0 0</pose>
    </frame>
    <frame name='pelvis_to_torso' attached_to='pelvis_link'>
      <pose>0 0 0.40999999999999998 0 0 0</pose>
    </frame>
    <frame name='torso_link' attached_to='pelvis_to_torso'>
      <pose>0 0 0 0 0 0</pose>
    </frame>
    <frame name='base_to_pelvis' attached_to='base_link'>
      <pose>0 0 0.84999999999999998 0 0 0</pose>
    </frame>
    <frame name='pelvis_link' attached_to='base_to_pelvis'>
      <pose>0 0 0 0 0 0</pose>
    </frame>
  </model>
</sdf>
